/*	8-5 
 * 아래의 코드가 수행되었을 때의 실행결과를 적으시오.
 */
public class prac108_05 {
	static void method(boolean b) {
		try {
			System.out.println(1);
			if(b) throw new ArithmeticException();
			System.out.println(2);
		} catch(RuntimeException r) {
			System.out.println(3);
			return;
		} catch(Exception e) {
			System.out.println(4);
			return;
		} finally {
			System.out.println(5);
		}
		
		System.out.println(6);
	}
	
	public static void main(String[] args) {
		method(true);
		method(false);
	} // main
}

/* 실행결과
 *  예상..
 * 1
 * 4
 * 5
 * 6-------여기 틀림... > ArithmeticException은 RuntimeException의 자손... Exception의 자손으로 생각...
 * 
 * >> 1 출력 > ArithmeticException 발생 > catch(RuntimeException r)에서 3출력 후 return 하기 전, 	
 * 		finally는 return 상관없이 출력하므로, 5출력 후 return으로 인헤서 메서도 종료.
 * 그리고, method(false) 실행 1256 (줄바꿈) 출력..
 * 1
 * 2
 * 5
 * 6
=======================
 * 
 * 콘솔 확인
 * 1
 * 3
 * 5
 * 1
 * 2
 * 5
 * 6
 * 
 */

